:actor_name:train
[ERROR 2022-04-25 18:46:45,485] function_runner.py: 281  Runner Thread raised error.
Traceback (most recent call last):
  File "/Users/alopo/miniconda3/envs/advanced_ai/lib/python3.7/site-packages/ray/tune/function_runner.py", line 272, in run
    self._entrypoint()
  File "/Users/alopo/miniconda3/envs/advanced_ai/lib/python3.7/site-packages/ray/tune/function_runner.py", line 351, in entrypoint
    self._status_reporter.get_checkpoint(),
  File "/Users/alopo/miniconda3/envs/advanced_ai/lib/python3.7/site-packages/ray/util/tracing/tracing_helper.py", line 462, in _resume_span
    return method(self, *_args, **_kwargs)
  File "/Users/alopo/miniconda3/envs/advanced_ai/lib/python3.7/site-packages/ray/tune/function_runner.py", line 640, in _trainable_func
    output = fn()
  File "/Users/alopo/Desktop/University/Advanced AI/CW/cross-modal-learning/main.py", line 32, in train
    text_datasets, vocabulary = dataUtils.load_data(config_data)
  File "/Users/alopo/Desktop/University/Advanced AI/CW/cross-modal-learning/Utils/dataUtils.py", line 121, in load_data
    audio_feats = h5py.File(feats_path, "r") #? read the h5py file
  File "/Users/alopo/miniconda3/envs/advanced_ai/lib/python3.7/site-packages/h5py/_hl/files.py", line 408, in __init__
    swmr=swmr)
  File "/Users/alopo/miniconda3/envs/advanced_ai/lib/python3.7/site-packages/h5py/_hl/files.py", line 173, in make_fid
    fid = h5f.open(name, flags, fapl=fapl)
  File "h5py/_objects.pyx", line 54, in h5py._objects.with_phil.wrapper
  File "h5py/_objects.pyx", line 55, in h5py._objects.with_phil.wrapper
  File "h5py/h5f.pyx", line 88, in h5py.h5f.open
OSError: Unable to open file (unable to open file: name = 'SavedData/audio_logmel.hdf5', errno = 2, error message = 'No such file or directory', flags = 0, o_flags = 0)
Exception in thread Thread-3:
Traceback (most recent call last):
  File "/Users/alopo/miniconda3/envs/advanced_ai/lib/python3.7/threading.py", line 926, in _bootstrap_inner
    self.run()
  File "/Users/alopo/miniconda3/envs/advanced_ai/lib/python3.7/site-packages/ray/tune/function_runner.py", line 298, in run
    raise e
  File "/Users/alopo/miniconda3/envs/advanced_ai/lib/python3.7/site-packages/ray/tune/function_runner.py", line 272, in run
    self._entrypoint()
  File "/Users/alopo/miniconda3/envs/advanced_ai/lib/python3.7/site-packages/ray/tune/function_runner.py", line 351, in entrypoint
    self._status_reporter.get_checkpoint(),
  File "/Users/alopo/miniconda3/envs/advanced_ai/lib/python3.7/site-packages/ray/util/tracing/tracing_helper.py", line 462, in _resume_span
    return method(self, *_args, **_kwargs)
  File "/Users/alopo/miniconda3/envs/advanced_ai/lib/python3.7/site-packages/ray/tune/function_runner.py", line 640, in _trainable_func
    output = fn()
  File "/Users/alopo/Desktop/University/Advanced AI/CW/cross-modal-learning/main.py", line 32, in train
    text_datasets, vocabulary = dataUtils.load_data(config_data)
  File "/Users/alopo/Desktop/University/Advanced AI/CW/cross-modal-learning/Utils/dataUtils.py", line 121, in load_data
    audio_feats = h5py.File(feats_path, "r") #? read the h5py file
  File "/Users/alopo/miniconda3/envs/advanced_ai/lib/python3.7/site-packages/h5py/_hl/files.py", line 408, in __init__
    swmr=swmr)
  File "/Users/alopo/miniconda3/envs/advanced_ai/lib/python3.7/site-packages/h5py/_hl/files.py", line 173, in make_fid
    fid = h5f.open(name, flags, fapl=fapl)
  File "h5py/_objects.pyx", line 54, in h5py._objects.with_phil.wrapper
  File "h5py/_objects.pyx", line 55, in h5py._objects.with_phil.wrapper
  File "h5py/h5f.pyx", line 88, in h5py.h5f.open
OSError: Unable to open file (unable to open file: name = 'SavedData/audio_logmel.hdf5', errno = 2, error message = 'No such file or directory', flags = 0, o_flags = 0)

